<?xml version="1.0"?>
<robot name="tr10">  
  <gazebo>
    <plugin name="differential_drive_controller" filename="libgazebo_ros_diff_drive.so">
      <legacyMode>false</legacyMode>
      <alwaysOn>true</alwaysOn>
      <updateRate>10</updateRate>
      <leftJoint>joint_base_wheel_left</leftJoint>
      <rightJoint>joint_base_wheel_right</rightJoint>
      <wheelSeparation>0.2</wheelSeparation>
      <wheelDiameter>0.05</wheelDiameter>
      <torque>20</torque>
      <commandTopic>cmd_vel</commandTopic>
      <odometryTopic>odom</odometryTopic>
      <odometryFrame>odom</odometryFrame>
      <robotBaseFrame>base_footprint</robotBaseFrame>
    </plugin>
  </gazebo>

  <gazebo reference="laser_link">
    <sensor type="ray" name="head_laser_sensor">
      <pose>0 0 0 0 0 0</pose>
      <visualize>true</visualize>
      <update_rate>40</update_rate>
      <ray>
        <scan>
          <horizontal>
            <samples>720</samples>
            <resolution>1</resolution>
            <min_angle>-1.570796</min_angle>
            <max_angle>1.570796</max_angle>
          </horizontal>
        </scan>
        <range>
          <min>0.10</min>
          <max>30.0</max>
          <resolution>0.01</resolution>
        </range>
        <noise>
          <type>gaussian</type>
          <mean>0.0</mean>
          <stddev>0.01</stddev>
        </noise>
      </ray>
      <plugin name="gazebo_ros_head_hokuyo_controller" filename="libgazebo_ros_laser.so">
        <topicName>/scan</topicName>
        <frameName>laser_link</frameName>
      </plugin>
    </sensor>
  </gazebo>

  <link name="base_link">  
    <visual>  
       <geometry>  
         <box size="0.3 0.2 0.1"/>  
       </geometry>  
       <origin rpy="0 0 0" xyz="0 0 0.05"/>  
       <material name="white">  
         <color rgba="1 1 1 1"/>  
       </material>  
    </visual>  
    <collision>
      <geometry>
         <box size="0.3 0.2 0.1"/>  
      </geometry>
       <origin rpy="0 0 0" xyz="0 0 0.05"/>  
    </collision>
    <inertial>
        <mass value="3"/>
        <inertia ixx="0.0125" ixy="0.0" ixz="0.0" iyy="0.025" iyz="0.0" izz="0.0325" />
    </inertial>
  </link>  
  
  <link name="laser_link">  
    <visual>  
        <geometry>  
             <cylinder length="0.05" radius="0.02"/>  
        </geometry>  
        <material name="black">  
          <color rgba="0 0 0 1"/>  
        </material>  
    </visual>  
    <collision>
        <geometry>
            <cylinder length="0.05" radius="0.02"/>  
        </geometry>
    </collision>
    <inertial>
        <mass value="0.2"/>
        <inertia ixx="0.0001667" ixy="0.0" ixz="0.0" iyy="0.0001667" iyz="0.0" izz="0.00025" />
    </inertial>
  </link>  

  <link name="wheel_left">  
    <visual>  
      <geometry>  
        <cylinder length="0.05" radius="0.05"/>  
      </geometry>  
      <origin rpy="1.5707963265 0 0"/>  
      <material name="black">  
        <color rgba="0 0 0 1"/>  
      </material>  
    </visual>  
    <collision>
      <geometry>
        <cylinder length="0.05" radius="0.05"/>  
      </geometry>
      <origin rpy="1.5707963265 0 0"/>  
    </collision>
    <inertial>
        <mass value="0.2"/>
        <inertia ixx="0.0001667" ixy="0.0" ixz="0.0" iyy="0.0001667" iyz="0.0" izz="0.00025" />
    </inertial>
  </link>  
  
  <link name="wheel_right">  
    <visual>  
      <geometry>  
        <cylinder length="0.05" radius="0.05"/>  
      </geometry>  
      <origin rpy="1.5707963265 0 0"/>  
      <material name="black"/>  
    </visual>  
    <collision>
      <geometry>
        <cylinder length="0.05" radius="0.05"/>  
      </geometry>
      <origin rpy="1.5707963265 0 0"/>  
    </collision>
    <inertial>
       <mass value="0.2"/>
       <inertia ixx="0.0001667" ixy="0.0" ixz="0.0" iyy="0.0001667" iyz="0.0" izz="0.00025" />
    </inertial>
  </link>  
  
  <link name="wheel_back">  
    <visual>  
      <geometry>  
        <sphere radius="0.05" />
      </geometry>  
      <origin rpy="1.5707963265 0 0"/>  
      <material name="black"/>  
    </visual>  
    <collision>
      <geometry>
        <sphere radius="0.05" />
      </geometry>
      <origin rpy="0 0 0"/>  
    </collision>
    <inertial>
        <mass value="0.002"/>
        <inertia ixx="0.000002" ixy="0.0" ixz="0.0" iyy="0.000002" iyz="0.0" izz="0.000002" />
    </inertial>
  </link>  
  
  <joint name="joint_base_laser" type="fixed">  
    <parent link="base_link"/>  
    <child link="laser_link"/>  
    <axis xyz="0 0 0"/>
    <origin xyz="0 0 0.125"/>  
  </joint>  

  <joint name="joint_base_wheel_left" type="continuous">  
    <parent link="base_link"/>  
    <child link="wheel_left"/>  
    <axis xyz="0 1 0"/>
    <origin xyz="0.1 0.1 0"/>  
  </joint>  
  
  <joint name="joint_base_wheel_right" type="continuous">  
    <parent link="base_link"/>  
    <child link="wheel_right"/>  
    <axis xyz="0 1 0"/>
    <origin xyz="0.1 -0.1 0"/>  
  </joint>  
  
  <joint name="joint_base_wheel_back" type="continuous">  
    <parent link="base_link"/>  
    <child link="wheel_back"/>  
    <axis xyz="0 0 1"/>
    <origin xyz="-0.1 0 0"/>  
  </joint>  
</robot> 
