<?xml version="1.0"?>
<robot name="tr10">  
  <gazebo>
    <plugin name="differential_drive_controller" filename="libgazebo_ros_diff_drive.so">
      <legacyMode>false</legacyMode>
      <alwaysOn>true</alwaysOn>
      <updateRate>10</updateRate>
      <leftJoint>joint_base_wheel1</leftJoint>
      <rightJoint>joint_base_wheel2</rightJoint>
      <wheelSeparation>0.2</wheelSeparation>
      <wheelDiameter>0.05</wheelDiameter>
      <torque>20</torque>
      <commandTopic>cmd_vel</commandTopic>
      <odometryTopic>odom</odometryTopic>
      <odometryFrame>odom</odometryFrame>
      <robotBaseFrame>base_footprint</robotBaseFrame>
    </plugin>
  </gazebo>

  <link name="base_link">  
    <visual>  
       <geometry>  
         <box size="0.3 0.2 0.1"/>  
       </geometry>  
       <origin rpy="0 0 0" xyz="0 0 0.05"/>  
       <material name="white">  
         <color rgba="1 1 1 1"/>  
       </material>  
    </visual>  
    <collision>
      <geometry>
         <box size="0.3 0.2 0.1"/>  
      </geometry>
       <origin rpy="0 0 0" xyz="0 0 0.05"/>  
    </collision>
    <inertial>
        <mass value="3"/>
        <inertia ixx="0.0125" ixy="0.0" ixz="0.0" iyy="0.025" iyz="0.0" izz="0.0325" />
    </inertial>
  </link>  
  
  <link name="wheel_1">  
    <visual>  
      <geometry>  
        <cylinder length="0.05" radius="0.05"/>  
      </geometry>  
      <origin rpy="1.5707963265 0 0"/>  
      <material name="black">  
        <color rgba="0 0 0 1"/>  
      </material>  
    </visual>  
    <collision>
      <geometry>
        <cylinder length="0.05" radius="0.05"/>  
      </geometry>
      <origin rpy="1.5707963265 0 0"/>  
    </collision>
    <inertial>
        <mass value="0.2"/>
        <inertia ixx="0.0001667" ixy="0.0" ixz="0.0" iyy="0.0001667" iyz="0.0" izz="0.00025" />
    </inertial>
  </link>  
  
  <link name="wheel_2">  
    <visual>  
      <geometry>  
        <cylinder length="0.05" radius="0.05"/>  
      </geometry>  
      <origin rpy="1.5707963265 0 0"/>  
      <material name="black"/>  
    </visual>  
    <collision>
      <geometry>
        <cylinder length="0.05" radius="0.05"/>  
      </geometry>
      <origin rpy="1.5707963265 0 0"/>  
    </collision>
    <inertial>
       <mass value="0.2"/>
       <inertia ixx="0.0001667" ixy="0.0" ixz="0.0" iyy="0.0001667" iyz="0.0" izz="0.00025" />
    </inertial>
  </link>  
  
  <link name="wheel_3">  
    <visual>  
      <geometry>  
        <sphere radius="0.05"/>  
      </geometry>  
      <origin rpy="1.5707963265 0 0"/>  
      <material name="black"/>  
    </visual>  
    <collision>
      <geometry>
        <sphere radius="0.05"/>  
      </geometry>
      <origin rpy="0 0 0"/>  
    </collision>
    <inertial>
        <mass value="0.002"/>
        <inertia ixx="0.000002" ixy="0.0" ixz="0.0" iyy="0.000002" iyz="0.0" izz="0.000002" />
    </inertial>
  </link>  
  
  <joint name="joint_base_wheel1" type="continuous">  
    <parent link="base_link"/>  
    <child link="wheel_1"/>  
    <axis xyz="0 1 0"/>
    <origin xyz="0.1 0.1 0"/>  
  </joint>  
  
  <joint name="joint_base_wheel2" type="continuous">  
    <parent link="base_link"/>  
    <child link="wheel_2"/>  
    <axis xyz="0 1 0"/>
    <origin xyz="0.1 -0.1 0"/>  
  </joint>  
  
  <joint name="joint_base_wheel3" type="continuous">  
    <parent link="base_link"/>  
    <child link="wheel_3"/>  
    <axis xyz="0 0 1"/>
    <origin xyz="-0.1 0 0"/>  
  </joint>  
</robot> 
